Workbook
Name Slicer_Lead_Type: #N/A
Name Slicer_Steps: #N/A
Name Slicer_Store_Name: #N/A

Sheet DASHBOARD
E23: Total Leads | F23: Conversion Rate | G23: Cancellation Rate | H23: Avg. Customer Rating | I23: Avg. Total TAT | J23: Avg.NPS
E24: =COUNTA(RawData!A2:A1001) -> 1000 | F24: =AVERAGE(FunnelAnalysis!B7/FunnelAnalysis!B5)*100 -> 81.2 | G24: =(GETPIVOTDATA("Cancellation Reason",CancellationAnalysis!$A$3)/DASHBOARD!E24)*100 -> 27.1 | H24: =AVERAGE('Customer Rating'!B19:B22) -> 4.8588374 | I24: =TATAnalysis!B10 -> 10.583744 | J24: =AVERAGE(StoreAnalysis!E21:E24) -> -53.077339

Sheet RawData
A1: Lead ID | B1: Store Name | C1: Lead Type | D1: Lead Date | E1: Pre-Booking Date | F1: Booking Date | G1: Delivery Date | H1: Cancellation Status | I1: Cancellation Reason | J1: Service Follow-up Date | K1: TAT Pre-Booking (Days) | L1: TAT Booking (Days) | M1: TAT Delivery (Days) | N1: Customer Rating
A2: L1000 | B2: Bangalore MBC | C2: Warm | D2: 45951 | E2: 45955 | F2: 45959 | G2: 45964 | H2: No | J2: 45989 | K2: 4 | L2: 4 | M2: 5 | N2: 2
A3: L1001 | B3: Delhi MBC | C3: Warm | D3: 45941 | E3: 45944 | F3: 45949 | G3: 45956 | H3: No | J3: 45983 | K3: 3 | L3: 5 | M3: 7 | N3: 8
A4: L1002 | B4: Mumbai MBC | C4: Cold | D4: 45931 | H4: Yes | I4: Other
A5: L1003 | B5: Bangalore MBC | C5: Cold | D5: 45958 | H5: Yes | I5: Model Unavailable
A6: L1004 | B6: Delhi MBC | C6: Warm | D6: 45944 | E6: 45948 | F6: 45951 | G6: 45954 | H6: No | J6: 45973 | K6: 4 | L6: 3 | M6: 3 | N6: 8
A7: L1005 | B7: Delhi MBC | C7: Warm | D7: 45957 | E7: 45961 | F7: 45965 | G7: 45968 | H7: No | J7: 45983 | K7: 4 | L7: 4 | M7: 3 | N7: 9
A8: L1006 | B8: Mumbai MBC | C8: Hot | D8: 45946 | E8: 45950 | F8: 45951 | G8: 45958 | H8: No | J8: 45983 | K8: 4 | L8: 1 | M8: 7 | N8: 10
A9: L1007 | B9: Chennai MBC | C9: Warm | D9: 45934 | E9: 45935 | F9: 45938 | G9: 45945 | H9: Yes | I9: Changed Mind | K9: 1 | L9: 3 | M9: 7
A10: L1008 | B10: Bangalore MBC | C10: Hot | D10: 45944 | E10: 45947 | F10: 45950 | G10: 45955 | H10: No | J10: 45966 | K10: 3 | L10: 3 | M10: 5 | N10: 8
A11: L1009 | B11: Mumbai MBC | C11: Warm | D11: 45961 | E11: 45965 | F11: 45966 | G11: 45971 | H11: No | J11: 45983 | K11: 4 | L11: 1 | M11: 5 | N11: 6
A12: L1010 | B12: Bangalore MBC | C12: Cold | D12: 45942 | H12: Yes | I12: Other
A13: L1011 | B13: Delhi MBC | C13: Warm | D13: 45951 | E13: 45954 | F13: 45958 | G13: 45960 | H13: No | J13: 45971 | K13: 3 | L13: 4 | M13: 2 | N13: 0
A14: L1012 | B14: Delhi MBC | C14: Warm | D14: 45959 | E14: 45962 | F14: 45967 | G14: 45974 | H14: No | J14: 45991 | K14: 3 | L14: 5 | M14: 7 | N14: 10
A15: L1013 | B15: Chennai MBC | C15: Warm | D15: 45957 | E15: 45960 | F15: 45963 | G15: 45969 | H15: No | J15: 45998 | K15: 3 | L15: 3 | M15: 6 | N15: 2
A16: L1014 | B16: Delhi MBC | C16: Hot | D16: 45945 | E16: 45947 | F16: 45948 | G16: 45951 | H16: Yes | I16: Changed Mind | K16: 2 | L16: 1 | M16: 3
A17: L1015 | B17: Delhi MBC | C17: Warm | D17: 45953 | E17: 45957 | F17: 45962 | G17: 45967 | H17: No | J17: 45984 | K17: 4 | L17: 5 | M17: 5 | N17: 8
A18: L1016 | B18: Mumbai MBC | C18: Hot | D18: 45935 | E18: 45936 | F18: 45940 | G18: 45946 | H18: No | J18: 45956 | K18: 1 | L18: 4 | M18: 6 | N18: 2
A19: L1017 | B19: Bangalore MBC | C19: Hot | D19: 45944 | E19: 45945 | F19: 45948 | G19: 45953 | H19: No | J19: 45979 | K19: 1 | L19: 3 | M19: 5 | N19: 0
A20: L1018 | B20: Bangalore MBC | C20: Warm | D20: 45936 | E20: 45937 | F20: 45942 | G20: 45947 | H20: No | J20: 45972 | K20: 1 | L20: 5 | M20: 5 | N20: 5
A21: L1019 | B21: Mumbai MBC | C21: Warm | D21: 45954 | E21: 45955 | F21: 45960 | G21: 45962 | H21: No | J21: 45972 | K21: 1 | L21: 5 | M21: 2 | N21: 4
A22: L1020 | B22: Chennai MBC | C22: Warm | D22: 45947 | E22: 45951 | F22: 45953 | G22: 45960 | H22: No | J22: 45980 | K22: 4 | L22: 2 | M22: 7 | N22: 6
A23: L1021 | B23: Bangalore MBC | C23: Hot | D23: 45961 | E23: 45962 | F23: 45963 | G23: 45966 | H23: No | J23: 45995 | K23: 1 | L23: 1 | M23: 3 | N23: 3
A24: L1022 | B24: Delhi MBC | C24: Warm | D24: 45951 | E24: 45954 | F24: 45959 | G24: 45962 | H24: No | J24: 45978 | K24: 3 | L24: 5 | M24: 3 | N24: 8
A25: L1023 | B25: Bangalore MBC | C25: Warm | D25: 45939 | E25: 45941 | F25: 45945 | G25: 45949 | H25: No | J25: 45963 | K25: 2 | L25: 4 | M25: 4 | N25: 3
A26: L1024 | B26: Delhi MBC | C26: Warm | D26: 45950 | E26: 45955 | F26: 45957 | G26: 45964 | H26: No | J26: 45984 | K26: 5 | L26: 2 | M26: 7 | N26: 1
A27: L1025 | B27: Chennai MBC | C27: Warm | D27: 45956 | E27: 45957 | F27: 45962 | G27: 45964 | H27: No | J27: 45979 | K27: 1 | L27: 5 | M27: 2 | N27: 4
A28: L1026 | B28: Mumbai MBC | C28: Warm | D28: 45960 | E28: 45965 | F28: 45970 | G28: 45976 | H28: No | J28: 45996 | K28: 5 | L28: 5 | M28: 6 | N28: 1
... A30: L1028 | B30: Mumbai MBC | C30: Warm | D30: 45955 | E30: 45960 | F30: 45962 | G30: 45968 | H30: No | J30: 45978 | K30: 5 | L30: 2 | M30: 6 | N30: 3
A31: L1029 | B31: Bangalore MBC | C31: Cold | D31: 45946 | H31: Yes | I31: Changed Mind
A32: L1030 | B32: Delhi MBC | C32: Warm | D32: 45945 | E32: 45948 | F32: 45950 | G32: 45953 | H32: No | J32: 45967 | K32: 3 | L32: 2 | M32: 3 | N32: 3
A33: L1031 | B33: Mumbai MBC | C33: Warm | D33: 45944 | E33: 45945 | F33: 45946 | G33: 45950 | H33: No | J33: 45978 | K33: 1 | L33: 1 | M33: 4 | N33: 5
A34: L1032 | B34: Bangalore MBC | C34: Warm | D34: 45957 | E34: 45961 | F34: 45966 | G34: 45970 | H34: No | J34: 45984 | K34: 4 | L34: 5 | M34: 4 | N34: 3
A35: L1033 | B35: Delhi MBC | C35: Warm | D35: 45954 | E35: 45957 | F35: 45958 | G35: 45961 | H35: No | J35: 45974 | K35: 3 | L35: 1 | M35: 3 | N35: 3
A36: L1034 | B36: Mumbai MBC | C36: Cold | D36: 45949 | H36: Yes | I36: Model Unavailable
A37: L1035 | B37: Mumbai MBC | C37: Warm | D37: 45939 | E37: 45943 | F37: 45945 | G37: 45950 | H37: No | J37: 45976 | K37: 4 | L37: 2 | M37: 5 | N37: 9
A38: L1036 | B38: Bangalore MBC | C38: Warm | D38: 45941 | E38: 45942 | F38: 45943 | G38: 45945 | H38: Yes | I38: Financing Issue | K38: 1 | L38: 1 | M38: 2
A39: L1037 | B39: Bangalore MBC | C39: Warm | D39: 45958 | E39: 45961 | F39: 45965 | G39: 45969 | H39: No | J39: 45990 | K39: 3 | L39: 4 | M39: 4 | N39: 2
A40: L1038 | B40: Bangalore MBC | C40: Warm | D40: 45938 | E40: 45943 | F40: 45946 | G40: 45953 | H40: No | J40: 45965 | K40: 5 | L40: 3 | M40: 7 | N40: 9
A41: L1039 | B41: Delhi MBC | C41: Warm | D41: 45957 | E41: 45960 | F41: 45964 | G41: 45969 | H41: Yes | I41: Other | K41: 3 | L41: 4 | M41: 5
...

Sheet FunnelAnalysis
A2: Lead-to-Delivery FUNNEL ANALYSIS
A4: Steps | B4: Total Count | C4: % Conversion | D4: % Drop-off | F4: Lead ID | G4: (All)
A5: Lead Generation | B5: 1000 | D5: 0
A6: Pre-Booking | B6: 812 | C6: =(B6/B5)*100 -> 81.2 | D6: =(1-(B6/B5))*100 -> 18.8 | F6: Count of Lead ID | G6: Count of Pre-Booking Date | H6: Count of Booking Date | I6: Count of Delivery Date
A7: Booking | B7: 812 | C7: =(B7/B6)*100 -> 100 | D7: =(1-(B7/B6))*100 -> 0 | F7: 1000 | G7: 812 | H7: 812 | I7: 812
A8: Delivery | B8: 812 | C8: =(B8/B7)*100 -> 100 | D8: =(1-(B8/B7))*100 -> 0

Sheet StoreAnalysis
A3: Row Labels | B3: Total Leads | C3: Pre-Booking | D3: Booking | E3: Delivery | F3: Cancellation | G3: Avg Rating
A4: Bangalore MBC | B4: 263 | C4: 212 | D4: 212 | E4: 212 | F4: 72 | G4: 4.6701571
A5: Chennai MBC | B5: 212 | C5: 173 | D5: 173 | E5: 173 | F5: 59 | G5: 5.0130719
A6: Delhi MBC | B6: 263 | C6: 212 | D6: 212 | E6: 212 | F6: 77 | G6: 4.8978495
A7: Mumbai MBC | B7: 262 | C7: 215 | D7: 215 | E7: 215 | F7: 63 | G7: 4.8542714
A11: STORE ANALYSIS
A13: Row Labels | B13: Total Leads | C13: Pre-Bookings | D13: Booking | E13: Delivery | F13: Cancellation | G13: Avg Rating | H13: % Conversion | I13: % Cancellation
A14: =A4 -> Bangalore MBC | B14: =B4 -> 263 | C14: =C4 -> 212 | D14: =D4 -> 212 | E14: =E4 -> 212 | F14: =F4 -> 72 | G14: =G4 -> 4.6701571 | H14: =(E14/B14)*100 -> 80.608365 | I14: =(F14/B14)*100 -> 27.376426
A15: =A5 -> Chennai MBC | B15: =B5 -> 212 | C15: =C5 -> 173 | D15: =D5 -> 173 | E15: =E5 -> 173 | F15: =F5 -> 59 | G15: =G5 -> 5.0130719 | H15: =(E15/B15)*100 -> 81.603774 | I15: =(F15/B15)*100 -> 27.830189
A16: =A6 -> Delhi MBC | B16: =B6 -> 263 | C16: =C6 -> 212 | D16: =D6 -> 212 | E16: =E6 -> 212 | F16: =F6 -> 77 | G16: =G6 -> 4.8978495 | H16: =(E16/B16)*100 -> 80.608365 | I16: =(F16/B16)*100 -> 29.277567
A17: =A7 -> Mumbai MBC | B17: =B7 -> 262 | C17: =C7 -> 215 | D17: =D7 -> 215 | E17: =E7 -> 215 | F17: =F7 -> 63 | G17: =G7 -> 4.8542714 | H17: =(E17/B17)*100 -> 82.061069 | I17: =(F17/B17)*100 -> 24.045802
A19: NPS Score | K19: Store Name | L19: Delhi MBC
A20: =A13 -> Row Labels | B20: Promotors | C20: Demotors | D20: Passives | E20: NPS Score
A21: =A14 -> Bangalore MBC | B21: 23 | C21: 134 | D21: 34 | E21: =((B21-C21)/SUM(B21:D21)*100) -> -58.115183 | K21: Row Labels | L21: Count of Customer Rating
A22: =A15 -> Chennai MBC | B22: 28 | C22: 99 | D22: 26 | E22: =((B22-C22)/SUM(B22:D22)*100) -> -46.405229 | K22: 0 | L22: 10 | N22: Promotors | O22: =SUM(L31:L32) -> 30
A23: =A16 -> Delhi MBC | B23: 30 | C23: 123 | D23: 33 | E23: =((B23-C23)/SUM(B23:D23)*100) -> -50 | K23: 1 | L23: 21 | N23: Demotors | O23: =SUM(L22:L28) -> 123
A24: =A17 -> Mumbai MBC | B24: 23 | C24: 138 | D24: 38 | E24: =((B24-C24)/SUM(B24:D24)*100) -> -57.788945 | K24: 2 | L24: 21 | N24: Passives | O24: =SUM(L29:L30) -> 33
K25: 3 | L25: 16
K26: 4 | L26: 23
K27: 5 | L27: 10
K28: 6 | L28: 22
K29: 7 | L29: 19
K30: 8 | L30: 14
K31: 9 | L31: 19
K32: 10 | L32: 11
K33: (blank)
K34: Grand Total | L34: 186

Sheet LeadTypeAnalysis
A1: LEAD TYPE PERFORMANCE | J1: LEAD TYPE DISTRIBUTION BY STORE
A3: Row Labels | B3: Leads | C3: Pre-Bookings | D3: Bookings | E3: Deliveries | F3: Cancellations | G3: Avg Rating | J3: Count of Lead Type | K3: Column Labels
A4: Cold | B4: 188 | F4: 188 | J4: Row Labels | K4: Cold | L4: Hot | M4: Warm | N4: Grand Total
A5: Hot | B5: 303 | C5: 303 | D5: 303 | E5: 303 | F5: 303 | G5: 4.8736462 | J5: Bangalore MBC | K5: 51 | L5: 80 | M5: 132 | N5: 263
A6: Warm | B6: 509 | C6: 509 | D6: 509 | E6: 509 | F6: 509 | G6: 4.8362832 | J6: Chennai MBC | K6: 39 | L6: 70 | M6: 103 | N6: 212
A7: Grand Total | B7: 1000 | C7: 812 | D7: 812 | E7: 812 | F7: 1000 | G7: 4.8504801 | J7: Delhi MBC | K7: 51 | L7: 70 | M7: 142 | N7: 263
J8: Mumbai MBC | K8: 47 | L8: 83 | M8: 132 | N8: 262
J9: Grand Total | K9: 188 | L9: 303 | M9: 509 | N9: 1000
A10: Row Labels | B10: Leads | C10: Pre-Bookings | D10: Bookings | E10: Deliveries | F10: Cancellations | G10: Avg Rating
A11: {=A4:G7} -> Cold | B11: 188 | C11: 0 | D11: 0 | E11: 0 | F11: 188 | G11: 0
A12: Hot | B12: 303 | C12: 303 | D12: 303 | E12: 303 | F12: 303 | G12: 4.8736462
A13: Warm | B13: 509 | C13: 509 | D13: 509 | E13: 509 | F13: 509 | G13: 4.8362832
A14: Grand Total | B14: 1000 | C14: 812 | D14: 812 | E14: 812 | F14: 1000 | G14: 4.8504801

Sheet TATAnalysis
A1: TOTAL TURNAROUND TIME (TAT) ANALYSIS
A3: Row Labels | B3: Avg TAT Pre-Bookings | C3: Avg TAT Booking | D3: Avg TAT Delivery
A4: Bangalore MBC | B4: 3.1179245 | C4: 3.0330189 | D4: 4.5141509
A5: Chennai MBC | B5: 3.1213873 | C5: 3.2023121 | D5: 4.3872832
A6: Delhi MBC | B6: 3.0283019 | C6: 3.0188679 | D6: 4.2830189
A7: Mumbai MBC | B7: 2.9767442 | C7: 3.0465116 | D7: 4.627907
A8: Grand Total | B8: 3.0578818 | C8: 3.0689655 | D8: 4.4568966
A10: Total TAT | B10: =SUM(B8:D8) -> 10.583744

Sheet CancellationAnalysis
A1: CANCELLATION ANALYSIS
A3: Row Labels | B3: Count of Cancellation Reason
A4: Changed Mind | B4: 51
A5: Financing Issue | B5: 59
A6: Model Unavailable | B6: 43
A7: Other | B7: 57
A8: Price | B8: 61
A9: Grand Total | B9: 271
A14: Count of Cancellation Reason | B14: Column Labels
A15: Row Labels | B15: Changed Mind | C15: Financing Issue | D15: Model Unavailable | E15: Other | F15: Price | G15: (blank)
A16: Bangalore MBC | B16: 13 | C16: 14 | D16: 13 | E16: 22 | F16: 10
A17: Chennai MBC | B17: 15 | C17: 10 | D17: 8 | E17: 8 | F17: 18
A18: Delhi MBC | B18: 14 | C18: 21 | D18: 13 | E18: 13 | F18: 16
A19: Mumbai MBC | B19: 9 | C19: 14 | D19: 9 | E19: 14 | F19: 17
A20: Grand Total | B20: 51 | C20: 59 | D20: 43 | E20: 57 | F20: 61

Sheet Customer Rating
A2: Row Labels | B2: Sum of Customer Rating
A3: 0 | B3: 0
A4: 1 | B4: 76
A5: 2 | B5: 166
A6: 3 | B6: 231
A7: 4 | B7: 320
A8: 5 | B8: 310
A9: 6 | B9: 480
A10: 7 | B10: 483
A11: 8 | B11: 496
A12: 9 | B12: 594
A13: 10 | B13: 380
A18: Row Labels | B18: Avg Customer Rating
A19: Bangalore MBC | B19: 4.6701571
A20: Chennai MBC | B20: 5.0130719
A21: Delhi MBC | B21: 4.8978495
A22: Mumbai MBC | B22: 4.8542714
